Workbook

Sheet Lord Character Sheet
A1: Abyss Lord TRPG — Dungeon Lord Character Sheet (Auto-Calc Version)
A2: Blue text = auto-calculated by formula, dark-purple fill = manual input
A3: Dungeon Name: | G3: Lord Name:
A4: Archetype: | G4: Dungeon Level:
A6: Lord Attributes
A7: CUN Cunning | D7: =MIN(IF(I4>=10,6,5), B7+C7) | E7: =D7&"d6"
A8: DOM Dominion | D8: =MIN(IF(I4>=10,6,5), B8+C8) | E8: =D8&"d6"
A9: ARC Arcana | D9: =MIN(IF(I4>=10,6,5), B9+C9) | E9: =D9&"d6"
A10: IND Industry | D10: =MIN(IF(I4>=10,6,5), B10+C10) | E10: =D10&"d6"
A11: WAR Warfare | D11: =MIN(IF(I4>=10,6,5), B11+C11) | E11: =D11&"d6"
A13: Lord Combat Panel
A14: Max HP | B14: =MAX(5, D8+D11) | C14: Current HP | E14: Physical Attack Dice | F14: =D11&"d6" | G14: Magic Attack Dice | H14: =D9&"d6" | I14: Defense Stance (pick 1)
A15: □Will/DOM □Evasion/WAR □Barrier/ARC Defense Dice Pool = Attribute d6
A17: Dungeon Attributes
A18: DEP Depth | B18: =VLOOKUP(I4, Level Table!A:G, 3, FALSE) | D18: =IF(B18="—", C18, B18+C18)
A19: INF Infamy | B19: =VLOOKUP(I4, Level Table!A:G, 4, FALSE) | D19: =IF(B19="—", C19, B19+C19)
A20: DEF Defense | D20: =IF(B20="—", C20, B20+C20)
A21: WLH Wealth | D21: =IF(B21="—", C21, B21+C21)
A22: MAG Magic | D22: =IF(B22="—", C22, B22+C22)
A24: ="Storage Cap: ◆"&VLOOKUP(D21, Storage Table!A:E, 2, TRUE)&" ◇"&VLOOKUP(D21, Storage Table!A:E, 3, TRUE)&" ■"&VLOOKUP(D21, Storage Table!A:E, 4, TRUE)&" ●"&VLOOKUP(D21, Storage Table!A:E, 5, TRUE)
A26: Resources
A27: Dark Coins ◆ | C27: Cap: | D27: =VLOOKUP(D21, Storage Table!A:E, 2, TRUE) | E27: Income/round: | G27: Maintenance/round:
A28: Mana Crystals ◇ | C28: Cap: | D28: =VLOOKUP(D21, Storage Table!A:E, 3, TRUE) | E28: Income/round: | G28: Maintenance/round:
A29: Building Materials ■ | C29: Cap: | D29: =VLOOKUP(D21, Storage Table!A:E, 4, TRUE) | E29: Income/round: | G29: Maintenance/round:
A30: Soul Essence ● | C30: Cap: | D30: =VLOOKUP(D21, Storage Table!A:E, 5, TRUE) | E30: Income/round: | G30: Maintenance/round:
A31: Throne Room Output | B31: ◆×1/round | C31: Treasure Vault Interest | D31: =IF(D4="Ancient Wyrm", FLOOR(B27/10,1)&"◆/round", "—")
A33: Spell Slots & Magic
A34: Max Spell Slots | B34: =IF(D9>=2, 2+D9-2+0, 0) & " + Skill Bonus" | C34: Base spell slots = ARC value (when ARC≥2). Ritual Master Lv1/2/3/4 each +1, Cursecraft Lv3+ +1, Research Chamber Lv2/3 each +1.
A35: Prepared Spells | B35: =D9+2 & " units" | C35: Before each incursion, choose ARC+2 prepared spells from those learned.
A37: Skills (20 common skill trees, Lv 0-4)
A38: CUN | B38: Trap Master | D38: Espionage | F38: Stealth | H38: Poisoncraft
A39: DOM | B39: Interrogation Expert | D39: Leader Charisma | F39: Diplomatic Skill | H39: Strict Discipline
A40: ARC | B40: Mana Affinity | D40: Ritual Master | F40: Enchanting | H40: Cursecraft
A41: IND | B41: Master Builder | D41: Resource Management | F41: Smithing | H41: Engineering
A42: WAR | B42: Tactical Command | D42: Fear Aura | F42: Battlefield Adaptation | H42: War Cry
A44: Archetype Combat Arts & Common Combat Arts
A45: Archetype Art 1
A46: Archetype Art 2
A47: Archetype Art 3
A48: Archetype Art 4
...

Sheet Level Table
A1: Level | B1: EXP | C1: DEP | D1: INF | E1: Action | F1: Room | G1: ◆ Cap | H1: ◇ Cap | I1: ■ Cap | J1: ● Cap | K1: Unlock
A2: 1 | B2: 0 | C2: 1 | D2: 1 | E2: 2 | F2: 3 | G2: 30 | H2: 15 | I2: 20 | J2: 10 | K2: Basic
A3: 2 | B3: 10 | C3: 2 | D3: 2 | E3: 2 | F3: 5 | G3: 30 | H3: 15 | I3: 20 | J3: 10 | K3: Medium Cavern
A4: 3 | B4: 25 | C4: 3 | D4: 3 | E4: 3 | F4: 8 | G4: 30 | H4: 15 | I4: 20 | J4: 10 | K4: Archetype Lv3
A5: 4 | B5: 45 | C5: 5 | D5: 4 | E5: 3 | F5: 10 | G5: 60 | H5: 30 | I5: 40 | J5: 20 | K5: —
A6: 5 | B6: 70 | C6: 7 | D6: 5 | E6: 3 | F6: 12 | G6: 60 | H6: 30 | I6: 40 | J6: 20 | K6: Elite monster, large dungeon palace
A7: 6 | B7: 100 | C7: 9 | D7: 6 | E7: 4 | F7: 15 | G7: 60 | H7: 30 | I7: 40 | J7: 20 | K7: Archetype Lv6
A8: 7 | B8: 140 | C8: 11 | D8: 7 | E8: 4 | F8: 18 | G8: 120 | H8: 60 | I8: 80 | J8: 40 | K8: Abyssal Hall
A9: 8 | B9: 190 | C9: 13 | D9: 8 | E9: 4 | F9: 22 | G9: 120 | H9: 60 | I9: 80 | J9: 40 | K9: —
A10: 9 | B10: 250 | C10: 15 | D10: 9 | E10: 5 | F10: 26 | G10: 120 | H10: 60 | I10: 80 | J10: 40 | K10: Archetype Lv9
A11: 10 | B11: 320 | C11: 18 | D11: 10 | E11: 5 | F11: 30 | G11: 250 | H11: 120 | I11: 160 | J11: 80 | K11: Legendary monster, attribute cap +1
A12: 11 | B12: 400 | C12: 21 | D12: 11 | E12: 5 | F12: 35 | G12: 250 | H12: 120 | I12: 160 | J12: 80 | K12: —
A13: 12 | B13: 500 | C13: 24 | D13: 12 | E13: 6 | F13: 40 | G13: 250 | H13: 120 | I13: 160 | J13: 80 | K13: —
... A16: 15 | B16: 920 | C16: 34 | D16: 15 | E16: 7 | F16: 60 | G16: 500 | H16: 250 | I16: 300 | J16: 150 | K16: Ultimate Ability

Sheet Storage Table
A1: WLH Cap | B1: ◆ | C1: ◇ | D1: ■ | E1: ●
A2: 3 | B2: 30 | C2: 15 | D2: 20 | E2: 10
A3: 6 | B3: 60 | C3: 30 | D3: 40 | E3: 20
A4: 9 | B4: 120 | C4: 60 | D4: 80 | E4: 40
A5: 12 | B5: 250 | C5: 120 | D5: 160 | E5: 80
A6: 15 | B6: 500 | C6: 250 | D6: 300 | E6: 150
